#VRML_SIM R2023b utf8

EXTERNPROTO "https://raw.githubusercontent.com/cyberbotics/webots/R2023b/projects/appearances/protos/OsbWood.proto"
EXTERNPROTO "https://raw.githubusercontent.com/cyberbotics/webots/R2023b/projects/objects/floors/protos/RectangleArena.proto"
EXTERNPROTO "https://raw.githubusercontent.com/cyberbotics/webots/R2023b/projects/objects/backgrounds/protos/TexturedBackground.proto"
EXTERNPROTO "https://raw.githubusercontent.com/cyberbotics/webots/R2023b/projects/objects/backgrounds/protos/TexturedBackgroundLight.proto"

WorldInfo {
  info [
    "In this example, the robot turns on a slope."
    "Its accelerometer sensor is used to switch on the bottommost LED."
  ]
  title "Accelerometer"
  basicTimeStep 8
  contactProperties [
    ContactProperties {
      material2 "body"
      coulombFriction [
        0
      ]
      softCFM 0.1
    }
  ]
}
Viewpoint {
  orientation -0.1532947541883355 -0.03322718315864176 0.9876217254787786 3.756478019191444
  position 0.7390054169246648 0.5590865856999265 0.47392647092345563
}
TexturedBackground {
}
TexturedBackgroundLight {
}
RectangleArena {
}
PointLight {
  attenuation 0 0 1
  intensity 0.6
  location 0.6 0 0
}
DEF SLOPE Solid {
  translation 0 0 0.15
  rotation 1 0 0 -1.970795
  children [
    Shape {
      appearance OsbWood {
        textureTransform TextureTransform {
          scale 0.5 2
        }
      }
      geometry DEF BOX0 Box {
        size 0.2 0.02 0.8
      }
    }
  ]
  name "green box"
  boundingObject USE BOX0
}
Robot {
  translation -4.93250996456694e-07 0.00960376642103273 0.1569019001992303
  rotation -0.23876055729035997 0.23872333145376404 0.9412781561802084 1.6310841418750825
  children [
    Accelerometer {
    }
    Pose {
      translation 0 0 0.0415
      children [
        Shape {
          appearance PBRAppearance {
            baseColor 0.0820075 0.364731 0.8
            roughness 1
            metalness 0
          }
          geometry DEF BODY Cylinder {
            height 0.08
            radius 0.045
          }
        }
      ]
    }
    HingeJoint {
      jointParameters HingeJointParameters {
        position 2.8639077133556642e-08
        axis 0 1 0
        anchor 0 0 0.025
      }
      device [
        RotationalMotor {
          name "left wheel motor"
          consumptionFactor 70
        }
        PositionSensor {
          name "left wheel sensor"
        }
      ]
      endPoint Solid {
        translation 0 0.045 0.025
        rotation 0.5773502636780331 -0.5773502636780321 -0.5773502802128121 2.094394983465221
        children [
          DEF WHEEL Pose {
            rotation 0.577656895078166 0.5771968951617173 -0.5771968951617173 -2.093935
            children [
              Shape {
                appearance PBRAppearance {
                  baseColor 1 0 0
                  roughness 1
                  metalness 0
                }
                geometry Cylinder {
                  height 0.01
                  radius 0.025
                }
              }
            ]
          }
        ]
        name "left wheel"
        boundingObject USE WHEEL
        physics DEF PHYSICS_WHEEL Physics {
          density -1
          mass 0.05
        }
        linearVelocity 1.4420628713552882e-13 5.275438438096909e-06 -2.230415962588859e-06
        angularVelocity 9.220539812116612e-09 2.146502736421353e-08 5.071171931023706e-08
      }
    }
    HingeJoint {
      jointParameters HingeJointParameters {
        position 2.866373868811343e-08
        axis 0 1 0
        anchor 0 0 0.025
      }
      device [
        RotationalMotor {
          name "right wheel motor"
          consumptionFactor 70
        }
        PositionSensor {
          name "right wheel sensor"
        }
      ]
      endPoint Solid {
        translation 0 -0.045 0.025
        rotation 0.5773502636732869 -0.577350263673286 -0.5773502802223043 2.0943949834509827
        children [
          USE WHEEL
        ]
        boundingObject USE WHEEL
        physics USE PHYSICS_WHEEL
        linearVelocity 9.852507493044795e-13 5.280002437934575e-06 -2.2323479138694025e-06
        angularVelocity 9.219275188999771e-09 2.146501396749697e-08 5.0711730908755045e-08
      }
    }
    DistanceSensor {
      translation 0.042 0.02 0.063
      rotation 0 0 -1 -0.499205
      children [
        DEF SENSOR Pose {
          rotation 0.577656895078166 0.5771968951617173 -0.5771968951617173 -2.093935
          children [
            Shape {
              appearance PBRAppearance {
                baseColor 0.975691 0.981481 0.0252992
                roughness 1
                metalness 0
              }
              geometry Cylinder {
                height 0.004
                radius 0.008
              }
            }
          ]
        }
      ]
      name "ds0"
      lookupTable [
        0 1024 0
        0.05 1024 0
        0.15 0 0
      ]
      numberOfRays 2
      aperture 1
    }
    DistanceSensor {
      translation 0.042 -0.02 0.063
      rotation 0 0 1 -0.500795
      children [
        USE SENSOR
      ]
      name "ds1"
      lookupTable [
        0 1024 0
        0.05 1024 0
        0.15 0 0
      ]
      numberOfRays 2
      aperture 1
    }
    DEF SMILE Pose {
      translation 0.036 0 0.025
      rotation 0 0 1 -0.5007953071795859
      children [
        Shape {
          appearance PBRAppearance {
            baseColor 0.721569 0.290196 0.290196
            roughness 1
            metalness 0
          }
          geometry Cylinder {
            height 0.018
            radius 0.009
            subdivision 3
          }
        }
      ]
    }
  ]
  name "MyBot"
  contactMaterial "body"
  boundingObject Pose {
    translation 0 0 0.0415
    rotation 0 0 1 -1.570796
    children [
      USE BODY
    ]
  }
  physics Physics {
    density -1
    mass 0.5
  }
  controller ""
  linearVelocity -8.683672624014488e-11 5.277586632375257e-06 -2.2313095259302504e-06
  angularVelocity 9.220130499287883e-09 2.1465008693661188e-08 5.0711733849433315e-08
}
